Workbook

Sheet Sheet1
A1: METRLA | B1: Horizon 36 | E1: Horizon 72 | H1: Horizon 144 | K1: Average | N1: PEMSBAY | O1: Horizon 36 | R1: Horizon 72 | U1: Horizon 144 | X1: Average
B2: MAE | C2: RMSE | D2: MAPE | E2: MAE | F2: RMSE | G2: MAPE | H2: MAE | I2: RMSE | J2: MAPE | K2: MAE | L2: RMSE | M2: MAPE | O2: MAE | P2: RMSE | Q2: MAPE | R2: MAE | S2: RMSE | T2: MAPE | U2: MAE | V2: RMSE | W2: MAPE | X2: MAE | Y2: RMSE | Z2: MAPE
A3: CSDI | B3: 12.81856 | C3: 22.770356 | D3: 0.26950468 | E3: 13.865955 | F3: 24.37742 | G3: 0.26623245 | H3: 13.323512 | I3: 23.456883 | J3: 0.23306439 | K3: 12.857417 | L3: 22.972273 | M3: 0.25163787 | O3: 4.569229 | P3: 9.586666 | Q3: 0.12908091 | R3: 4.821365 | S3: 9.814941 | T3: 0.13490815 | U3: 3.913944 | V3: 8.176395 | W3: 0.1017539 | X3: 4.403869 | Y3: 9.23242 | Z3: 0.12154108
A4: STAEformer | B4: 4.15513 | C4: 8.64678 | D4: 0.1400131 | E4: 4.15054 | F4: 8.69 | G4: 0.1414331 | H4: 4.16183 | I4: 8.59797 | J4: 0.1413912 | K4: 4.15583 | L4: 8.64492 | M4: 0.140945 | O4: 2.35913 | P4: 5.3674 | Q4: 0.0556862 | R4: 2.40122 | S4: 5.45707 | T4: 0.0564007 | U4: 2.50719 | V4: 5.43954 | W4: 0.0602623 | X4: 2.35279 | Y4: 5.35285 | Z4: 0.0555926
A5: Linear | B5: 10.8054 | C5: 15.3537 | D5: 0.2441 | E5: 11.7739 | F5: 16.1893 | G5: 0.2634 | H5: 11.5217 | I5: 15.1806 | J5: 0.2598 | K5: 10.9048 | L5: 15.2529 | M5: 0.2421 | O5: 10.6122 | P5: 21.2919 | Q5: 0.2109 | R5: 8.5419 | S5: 14.6471 | T5: 0.1776 | U5: 9.3878 | V5: 17.8567 | W5: 0.1986 | X5: 8.3385 | Y5: 16.0325 | Z5: 0.1719
A6: VAR | B6: 11.1971 | C6: 20.1526 | D6: 0.2798 | E6: 13.4638 | F6: 22.6505 | G6: 0.331 | H6: 15.6336 | I6: 25.2522 | J6: 0.3822 | K6: 12.4064 | L6: 21.6558 | M6: 0.305 | O6: 6.1864 | P6: 12.8783 | Q6: 0.1595 | R6: 8.0628 | S6: 15.1032 | T6: 0.2059 | U6: 9.1874 | V6: 16.0153 | W6: 0.228 | X6: 7.1825 | Y6: 13.9526 | Z6: 0.1811
A7: DCRNN | B7: 5.6025 | C7: 11.4033 | D7: 0.174 | E7: 6.275 | F7: 12.4806 | G7: 0.2004 | H7: 7.0314 | I7: 13.302 | J7: 0.2306 | K7: 5.9233 | L7: 11.7415 | M7: 0.1878 | O7: 7.5442 | P7: 11.8997 | Q7: 0.1638 | R7: 10.2636 | S7: 13.9133 | T7: 0.2057 | U7: 13.066 | V7: 16.3699 | W7: 0.2437 | X7: 8.9557 | Y7: 12.8966 | Z7: 0.1835
A8: STGCN | B8: 4.4293 | C8: 8.8004 | D8: 0.1434 | E8: 4.5725 | F8: 9.1078 | G8: 0.1497 | H8: 4.7434 | I8: 9.3667 | J8: 0.1574 | K8: 4.4821 | L8: 8.8609 | M8: 0.1457 | O8: 2.6927 | P8: 5.5679 | Q8: 0.0655 | R8: 2.8236 | S8: 5.7739 | T8: 0.0682 | U8: 3.175 | V8: 6.6927 | W8: 0.0792 | X8: 2.757 | Y8: 5.6865 | Z8: 0.0671
A9: DGCRN | B9: 9.727 | C9: 16.5052 | D9: 0.3438 | E9: 9.8081 | F9: 16.6141 | G9: 0.3473 | H9: 9.7691 | I9: 16.5559 | J9: 0.3447 | K9: 9.3433 | L9: 15.8213 | M9: 0.3295 | O9: 2.7561 | P9: 6.0755 | Q9: 0.0666 | R9: 5.3652 | S9: 10.96 | T9: 0.1374 | U9: 7.5916 | V9: 14.0262 | W9: 0.1794 | X9: 4.7587 | Y9: 9.4617 | Z9: 0.1181
A10: DiffSTG | B10: 7.7634 | C10: 12.3057 | D10: 0.2167 | E10: 7.8586 | F10: 12.1823 | G10: 0.2263 | H10: 8.2852 | I10: 12.7684 | J10: 0.2376 | K10: 7.6547 | L10: 11.8263 | M10: 0.2191 | O10: 3.2179 | P10: 5.8296 | Q10: 0.086 | R10: 3.3874 | S10: 6.1289 | T10: 0.0905 | U10: 3.6192 | V10: 6.3932 | W10: 0.0948 | X10: 3.3697 | Y10: 5.9187 | Z10: 0.088
A11: HimNet | B11: 4.0602 | C11: 8.8021 | D11: 0.1307 | E11: 4.1036 | F11: 8.9445 | G11: 0.135 | H11: 4.1625 | I11: 9.1016 | J11: 0.1391 | K11: 4.1085 | L11: 9.0142 | M11: 0.1361 | O11: 2.6606 | P11: 6.0013 | Q11: 0.0644 | R11: 2.9641 | S11: 6.3648 | T11: 0.0702 | U11: 2.9765 | V11: 6.3541 | W11: 0.0717 | X11: 2.7506 | Y11: 6.0337 | Z11: 0.0658
A12: STID | B12: 4.7045 | C12: 9.8622 | D12: 0.1671 | E12: 4.7597 | F12: 9.8322 | G12: 0.1666 | H12: 4.5936 | I12: 9.3252 | J12: 0.1565 | K12: 4.6162 | L12: 9.4675 | M12: 0.1585 | O12: 2.7517 | P12: 5.9184 | Q12: 0.0704 | R12: 2.9832 | S12: 6.2482 | T12: 0.0756 | U12: 3.0389 | V12: 6.5646 | W12: 0.0779 | X12: 2.8481 | Y12: 6.0848 | Z12: 0.0724
A13: Transformer | B13: 7.3732 | C13: 13.1246 | D13: 0.1591 | E13: 7.6604 | F13: 13.7331 | G13: 0.1634 | H13: 7.901 | I13: 13.7551 | J13: 0.1681 | K13: 7.4173 | L13: 13.2574 | M13: 0.1595 | O13: 2.8424 | P13: 5.5753 | Q13: 0.0696 | R13: 2.8764 | S13: 5.5967 | T13: 0.0704 | U13: 3.1742 | V13: 6.0565 | W13: 0.0777 | X13: 2.8872 | Y13: 5.6118 | Z13: 0.0707
A14: Informer | B14: 7.7084 | C14: 12.7016 | D14: 0.1635 | E14: 8.1361 | F14: 13.504 | G14: 0.1728 | H14: 8.9829 | I14: 14.5042 | J14: 0.1899 | K14: 8.0848 | L14: 13.3241 | M14: 0.1712 | O14: 2.8782 | P14: 5.4947 | Q14: 0.0705 | R14: 2.9205 | S14: 5.7087 | T14: 0.0716 | U14: 3.2194 | V14: 6.3197 | W14: 0.0789 | X14: 2.9236 | Y14: 5.7028 | Z14: 0.0717
... A28: STUM | B28: 6.534 | C28: 10.185 | D28: 0.1869 | E28: 6.2952 | F28: 9.8818 | G28: 0.1868 | H28: 6.3419 | I28: 9.9294 | J28: 0.1884 | K28: 6.371 | L28: 10.1495 | M28: 0.1831 | O28: 3.2246 | P28: 5.9539 | Q28: 0.0793 | R28: 3.265 | S28: 5.9655 | T28: 0.0794 | U28: 3.3331 | V28: 6.2464 | W28: 0.083 | X28: 3.2541 | Y28: 6.0044 | Z28: 0.0796
B31: Horizon 3 | E31: Horizon 6 | H31: Horizon 12 | K31: Average
A32: PEMS08 | B32: MAE | C32: RMSE | D32: MAPE
A33: STAEformer | B33: 12.6875 | C33: 21.5429 | D33: 0.0829 | E33: 13.546 | F33: 23.3599 | G33: 0.0884 | H33: 14.8931 | I33: 25.6738 | J33: 0.0979 | K33: 13.5565 | L33: 23.3108 | M33: 0.0887
A34: HimNet | B34: 13.1555 | C34: 21.5647 | D34: 0.0875 | E34: 14.338 | F34: 23.63843 | G34: 0.0934 | H34: 14.3382 | I34: 23.6384 | J34: 0.1037 | K34: 14.3817 | L34: 23.6758 | M34: 0.0938
A35: TrafficFM | B35: 15.3177 | C35: 22.984 | D35: 0.1006 | E35: 16.3668 | F35: 25.6862 | G35: 0.1051 | H35: 17.8092 | I35: 28.102 | J35: 0.1063 | K35: 16.5898 | L35: 25.907 | M35: 0.105
A36: STGCN | B36: 15.9458 | C36: 24.2796 | D36: 0.1087 | E36: 17.1937 | F36: 26.4492 | G36: 0.1154 | H36: 20.0461 | I36: 30.6701 | J36: 0.1321 | K36: 17.4039 | L36: 26.7898 | M36: 0.1163
A37: STID | B37: 14.029 | C37: 22.1012 | D37: 0.0987 | E37: 15.3497 | F37: 24.2717 | G37: 0.1142 | H37: 17.5789 | I37: 27.524 | J37: 0.1327 | K37: 15.422 | L37: 24.3677 | M37: 0.1139
A38: STGCN | B38: 15.9458 | C38: 24.2796 | D38: 0.1087 | E38: 17.1937 | F38: 26.4492 | G38: 0.1154 | H38: 20.0461 | I38: 30.6701 | J38: 0.1321 | K38: 17.4039 | L38: 26.7898 | M38: 0.1163
A39: GWNET | B39: 15.5602 | C39: 24.3923 | D39: 0.1095 | E39: 17.2743 | F39: 27.5309 | G39: 0.1094 | H39: 20.7128 | I39: 33.0629 | J39: 0.1356 | K39: 17.4594 | L39: 27.9378 | M39: 0.1154
A41: METR-LA | B41: MAE | C41: CRPS | D41: WD | E41: PEMS-BAY | F41: MAE | G41: CRPS | H41: WD
A42: STGCN | B42: =Sheet2!E4 -> 4.7434 | C42: 4.5934 | D42: 1.4529 | F42: =Sheet2!E5 -> 3.175 | G42: 3.1791 | H42: 0.9784
A43: HimNet | B43: =Sheet2!E6 -> 4.1625 | C43: 4.1443 | D43: 1.9381 | F43: =Sheet2!E7 -> 2.9765 | G43: 2.9806 | H43: 1.3906
A44: TrafficFM | B44: =Sheet2!E8 -> 3.9905 | C44: 3.959 | D44: 1.3057 | F44: =Sheet2!E9 -> 2.6057 | G44: 2.611 | H44: 0.5761
A45: GWNET | B45: =Sheet2!E10 -> 5.0621 | C45: 5.1431 | D45: 1.1517 | F45: =Sheet2!E11 -> 2.8243 | G45: 2.7391 | H45: 1.0054
A46: STUM | B46: =Sheet2!E12 -> 6.3419 | C46: 5.189 | D46: 3.1514 | F46: =Sheet2!E13 -> 3.3331 | G46: 3.0678 | H46: 1.1841
A47: STID | B47: =Sheet2!E14 -> 4.5936 | C47: 6.2539 | D47: 1.3783 | F47: =Sheet2!E15 -> 3.0389 | G47: 2.7113 | H47: 0.835
A48: FreqFlow | B48: =Sheet2!E16 -> 10.3992 | C48: 8.556 | D48: 2.5603 | F48: =Sheet2!E17 -> 4.7232 | G48: 4.1972 | H48: 1.4844
A49: STAEformer | B49: =Sheet2!E18 -> 4.16183 | C49: 4.0337 | D49: 2.2145 | F49: =Sheet2!E19 -> 2.50719 | G49: 2.4292 | H49: 0.9369
A50: PatchSTG | B50: =Sheet2!E20 -> 4.3756 | C50: 4.1952 | D50: 1.3739 | F50: =Sheet2!E21 -> 2.6295 | G50: 2.565 | H50: 0.9651
A51: Inference Time (s) | B51: METR-LA | C51: PEMS-BAY
A52: STID | B52: 1.3384 | C52: 1.4489
A53: STUM | B53: 20.4737 | C53: 59.8687
A54: GWNET | B54: 20.5584 | C54: 53.5109
A55: UniST | B55: 68.6769 | C55: 156.1419
A56: STAEformer | B56: 222.4353 | C56: 323.7668
...

Sheet Sheet2
A1: Table II MAE Reconciliation Against Submitted main.pdf
A3: Method | B3: Dataset | C3: Table I H144 MAE | D3: Prior Table II MAE | E3: Reconciled MAE | F3: Prior - Table I | G3: CRPS/WD source | H3: Validation status
A4: STGCN | B4: METR-LA | C4: 4.7434 | D4: 4.7434 | E4: =C4 -> 4.7434 | F4: =D4-C4 -> 0 | G4: Submitted Table II | H4: Consistent
A5: STGCN | B5: PEMS-BAY | C5: 3.175 | D5: 3.175 | E5: =C5 -> 3.175 | F5: =D5-C5 -> 0 | G5: Submitted Table II | H5: Consistent
A6: HimNet | B6: METR-LA | C6: 4.1625 | D6: 4.1625 | E6: =C6 -> 4.1625 | F6: =D6-C6 -> 0 | G6: Submitted Table II | H6: Consistent
A7: HimNet | B7: PEMS-BAY | C7: 2.9765 | D7: 2.9765 | E7: =C7 -> 2.9765 | F7: =D7-C7 -> 0 | G7: Submitted Table II | H7: Consistent
A8: TrafficFM | B8: METR-LA | C8: 3.9905 | D8: 3.9897 | E8: =C8 -> 3.9905 | F8: =D8-C8 -> -0.0008 | G8: Submitted Table II | H8: MAE unified to Table I; retain submitted CRPS/WD
A9: TrafficFM | B9: PEMS-BAY | C9: 2.6057 | D9: 2.6069 | E9: =C9 -> 2.6057 | F9: =D9-C9 -> 0.0012 | G9: Submitted Table II | H9: MAE unified to Table I; retain submitted CRPS/WD
A10: GWNET | B10: METR-LA | C10: 5.0621 | D10: 5.0621 | E10: =C10 -> 5.0621 | F10: =D10-C10 -> 0 | G10: Supplemental run | H10: Consistent
A11: GWNET | B11: PEMS-BAY | C11: 2.8243 | D11: 2.8243 | E11: =C11 -> 2.8243 | F11: =D11-C11 -> 0 | G11: Supplemental run | H11: Consistent
A12: STUM | B12: METR-LA | C12: 6.3419 | D12: 6.3419 | E12: =C12 -> 6.3419 | F12: =D12-C12 -> 0 | G12: Supplemental run | H12: Consistent
A13: STUM | B13: PEMS-BAY | C13: 3.3331 | D13: 3.3331 | E13: =C13 -> 3.3331 | F13: =D13-C13 -> 0 | G13: Supplemental run | H13: Consistent
A14: STID | B14: METR-LA | C14: 4.5936 | D14: 7.0365 | E14: =C14 -> 4.5936 | F14: =D14-C14 -> 2.4429 | G14: Supplemental run | H14: Recompute CRPS/WD from the Table I prediction file
A15: STID | B15: PEMS-BAY | C15: 3.0389 | D15: 2.7543 | E15: =C15 -> 3.0389 | F15: =D15-C15 -> -0.2846 | G15: Supplemental run | H15: Recompute CRPS/WD from the Table I prediction file
... A21: PatchSTG | B21: PEMS-BAY | C21: 2.6295 | D21: 2.6241 | E21: =C21 -> 2.6295 | F21: =D21-C21 -> -0.0054 | G21: Supplemental run | H21: Recheck CRPS/WD with the saved Table I predictions
A23: DiffSTG status
A24: The DiffSTG probabilistic run was not complete by the rebuttal deadline because of its high runtime. Its implementation has been uploaded to the anonymous benchmark repository; no unfinished CRPS/WD values are reported.

Sheet Sheet3
A1: Experimental Results Reconciliation Notes
A3: Primary source | B3: Submitted main.pdf, Tables I-II
A4: Table II MAE | B4: Aligned to Table I Horizon 144 for every included model
A5: TrafficFM | B5: MAE unified to 3.9905 (METR-LA) and 2.6057 (PEMS-BAY); submitted CRPS/WD retained
A6: Duplicate row | B6: Removed the earlier conflicting PatchSTG row
A7: MAPE formatting | B7: Normalized CSDI/STAEformer percentage cells to consistent percentage units
A8: DiffSTG | B8: Code uploaded; probabilistic run incomplete at the rebuttal deadline; no result fabricated
A9: Important caveat | B9: STID, STAEformer, and PatchSTG CRPS/WD must be recomputed from the same saved predictions as Table I before being claimed as final
A11: Anonymous artifact update
A12: Implementations uploaded: CSDI, STAEformer, PatchSTG, GraphWaveNet, TSFlow, FreqFlow, UniST, STUM, and DiffSTG. Upload only verified supplementary metrics together with configurations, evaluator details, seeds, and raw outputs.
